{
 "cells": [
  {
   "cell_type": "code",
   "execution_count": 1,
   "id": "minor-television",
   "metadata": {},
   "outputs": [
    {
     "data": {
      "application/vnd.jupyter.widget-view+json": {
       "model_id": "e7594656782e4c009822de0f499ddb65",
       "version_major": 2,
       "version_minor": 0
      },
      "text/plain": [
       "VBox(children=(HTML(value='<h2>GatewayCluster</h2>'), HBox(children=(HTML(value='\\n<div>\\n<style scoped>\\n    â€¦"
      ]
     },
     "metadata": {},
     "output_type": "display_data"
    }
   ],
   "source": [
    "from matplotlib import pyplot as plt\n",
    "import numpy as np\n",
    "import pandas as pd\n",
    "import xarray as xr\n",
    "import zarr\n",
    "import gcsfs\n",
    "\n",
    "from dask_gateway import Gateway\n",
    "from dask.distributed import Client\n",
    "\n",
    "gateway = Gateway()\n",
    "cluster = gateway.new_cluster()\n",
    "cluster.scale(10)\n",
    "client = Client(cluster,timeout=\"120s\")\n",
    "cluster\n"
   ]
  },
  {
   "cell_type": "code",
   "execution_count": 18,
   "id": "surface-water",
   "metadata": {},
   "outputs": [],
   "source": [
    "df = pd.read_csv('https://storage.googleapis.com/cmip6/cmip6-zarr-consolidated-stores.csv')\n",
    "df.head()\n",
    "\n",
    "model_name='\"HadGEM3-GC31-LL\"'\n",
    "experiment='\"ssp585\"'\n",
    "\n",
    "test='source_id == '+ model_name +' & activity_id==\"CMIP\" & table_id == \"Omon\" & variable_id == \"thetao\" & experiment_id == '+experiment\n",
    "\n",
    "theta = df.query('source_id =='+ model_name +' & table_id == \"Omon\" & variable_id == \"thetao\" & experiment_id =='+ experiment+'& grid_label == \"gn\" & member_id == \"r1i1p1f3\"')\n",
    "\n",
    "uo = df.query('source_id =='+ model_name +' & table_id == \"Omon\" & variable_id == \"uo\" & experiment_id =='+ experiment+' & member_id == \"r1i1p1f3\"')\n",
    "vo = df.query('source_id =='+ model_name +' & table_id == \"Omon\" & variable_id == \"vo\" & experiment_id =='+ experiment+' & member_id == \"r1i1p1f3\"')\n",
    "wo = df.query('source_id =='+ model_name +' & table_id == \"Omon\" & variable_id == \"wo\" & experiment_id =='+ experiment+' & member_id == \"r1i1p1f3\"')\n",
    "tauu=df.query('source_id =='+ model_name +'& table_id == \"Amon\" & variable_id == \"tauu\" & experiment_id =='+ experiment+'& member_id == \"r1i1p1f3\"')\n",
    "tauv=df.query('source_id =='+ model_name +'& table_id == \"Amon\" & variable_id == \"tauu\" & experiment_id =='+ experiment+'& member_id == \"r1i1p1f3\"')\n",
    "\n",
    "hfls=df.query('source_id =='+ model_name +' & table_id == \"Amon\" & variable_id == \"hfls\" & experiment_id =='+ experiment+'& member_id == \"r1i1p1f3\"')\n",
    "hfss=df.query('source_id =='+ model_name +' & table_id == \"Amon\" & variable_id == \"hfss\" & experiment_id =='+ experiment+'& member_id == \"r1i1p1f3\"')\n",
    "rlds=df.query('source_id =='+ model_name +' & table_id == \"Amon\" & variable_id == \"rlds\" & experiment_id =='+ experiment+'& member_id == \"r1i1p1f3\"')\n",
    "rlus=df.query('source_id =='+ model_name +' & table_id == \"Amon\" & variable_id == \"rlus\" & experiment_id =='+ experiment+'& member_id == \"r1i1p1f3\"')\n",
    "rsds=df.query('source_id =='+ model_name +' & table_id == \"Amon\" & variable_id == \"rsds\" & experiment_id =='+ experiment+'& member_id == \"r1i1p1f3\"')\n",
    "rsus=df.query('source_id =='+ model_name +' & table_id == \"Amon\" & variable_id == \"rsus\" & experiment_id =='+ experiment+'& member_id == \"r1i1p1f3\"')\n",
    "\n",
    "\n",
    "def get_df(invar):\n",
    "# this only needs to be created once\n",
    "    gcs = gcsfs.GCSFileSystem(token='anon')\n",
    "\n",
    "# get the path to a specific zarr store (the first one from the dataframe above)\n",
    "    zstore = invar.zstore.values[-1]\n",
    "\n",
    "# create a mutable-mapping-style interface to the store\n",
    "    mapper = gcs.get_mapper(zstore)\n",
    "\n",
    "# open it using xarray and zarr\n",
    "    outvar = xr.open_zarr(mapper, consolidated=True)\n",
    "\n",
    "    return outvar\n",
    "\n",
    "theta_pi=get_df(theta)\n",
    "uo_pi=get_df(uo)\n",
    "vo_pi=get_df(vo)\n",
    "wo_pi=get_df(wo)\n",
    "tauu_pi=get_df(tauu)\n",
    "tauv_pi=get_df(tauv)\n",
    "hfls_pi=get_df(hfls)\n",
    "hfss_pi=get_df(hfss)\n",
    "rlds_pi=get_df(rlds)\n",
    "rlus_pi=get_df(rlus)\n",
    "rsds_pi=get_df(rsds)\n",
    "rsus_pi=get_df(rsus)\n"
   ]
  },
  {
   "cell_type": "code",
   "execution_count": 19,
   "id": "ecological-compromise",
   "metadata": {},
   "outputs": [],
   "source": [
    "theta_eq=theta_pi.sel(j=slice(170,200),lev=slice(0,500)).isel(time=slice(0,200*12))\n",
    "\n",
    "uo_eq=uo_pi.sel(j=slice(170,200)).sel(lev=slice(0,500)).isel(time=slice(0,200*12))\n",
    "vo_eq=vo_pi.sel(j=slice(170,200)).sel(lev=slice(0,500)).isel(time=slice(0,200*12))\n",
    "vo_eq=vo_eq.drop('vertices_latitude')\n",
    "vo_eq=vo_eq.drop('vertices_longitude')\n",
    "wo_eq=wo_pi.sel(j=slice(170,200)).sel(lev=slice(0,500)).isel(time=slice(0,200*12))\n",
    "wo_eq=wo_eq.drop('vertices_latitude')\n",
    "wo_eq=wo_eq.drop('vertices_longitude')\n",
    "tauu_eq=tauu_pi.sel(lat=slice(-5,5)).isel(time=slice(0,200*12))\n",
    "\n",
    "Q_pi=(rsds_pi['rsds']-rsus_pi['rsus'])-(rlus_pi['rlus']-rlds_pi['rlds'])-hfls_pi['hfls']-hfss_pi['hfss']\n",
    "\n",
    "Q_eq=Q_pi.sel(lat=slice(-5,5)).isel(time=slice(0,200*12))\n",
    "#theta_pi.nav_lat.load()"
   ]
  },
  {
   "cell_type": "code",
   "execution_count": 7,
   "id": "smaller-latino",
   "metadata": {},
   "outputs": [
    {
     "data": {
      "text/html": [
       "<div>\n",
       "<style scoped>\n",
       "    .dataframe tbody tr th:only-of-type {\n",
       "        vertical-align: middle;\n",
       "    }\n",
       "\n",
       "    .dataframe tbody tr th {\n",
       "        vertical-align: top;\n",
       "    }\n",
       "\n",
       "    .dataframe thead th {\n",
       "        text-align: right;\n",
       "    }\n",
       "</style>\n",
       "<table border=\"1\" class=\"dataframe\">\n",
       "  <thead>\n",
       "    <tr style=\"text-align: right;\">\n",
       "      <th></th>\n",
       "      <th>activity_id</th>\n",
       "      <th>institution_id</th>\n",
       "      <th>source_id</th>\n",
       "      <th>experiment_id</th>\n",
       "      <th>member_id</th>\n",
       "      <th>table_id</th>\n",
       "      <th>variable_id</th>\n",
       "      <th>grid_label</th>\n",
       "      <th>zstore</th>\n",
       "      <th>dcpp_init_year</th>\n",
       "      <th>version</th>\n",
       "    </tr>\n",
       "  </thead>\n",
       "  <tbody>\n",
       "  </tbody>\n",
       "</table>\n",
       "</div>"
      ],
      "text/plain": [
       "Empty DataFrame\n",
       "Columns: [activity_id, institution_id, source_id, experiment_id, member_id, table_id, variable_id, grid_label, zstore, dcpp_init_year, version]\n",
       "Index: []"
      ]
     },
     "execution_count": 7,
     "metadata": {},
     "output_type": "execute_result"
    }
   ],
   "source": [
    "theta"
   ]
  },
  {
   "cell_type": "code",
   "execution_count": 20,
   "id": "terminal-capitol",
   "metadata": {},
   "outputs": [
    {
     "name": "stdout",
     "output_type": "stream",
     "text": [
      "using dimensions ('j', 'i') from data variable thetao as the horizontal dimensions for this dataset.\n",
      "using dimensions ('j', 'i') from data variable uo as the horizontal dimensions for this dataset.\n",
      "using dimensions ('j', 'i') from data variable vo as the horizontal dimensions for this dataset.\n",
      "using dimensions ('j', 'i') from data variable wo as the horizontal dimensions for this dataset.\n"
     ]
    },
    {
     "name": "stderr",
     "output_type": "stream",
     "text": [
      "/srv/conda/envs/notebook/lib/python3.8/site-packages/xesmf/frontend.py:473: FutureWarning: ``output_sizes`` should be given in the ``dask_gufunc_kwargs`` parameter. It will be removed as direct parameter in a future version.\n",
      "  ds_out = xr.apply_ufunc(\n",
      "/srv/conda/envs/notebook/lib/python3.8/site-packages/xesmf/frontend.py:473: FutureWarning: ``output_sizes`` should be given in the ``dask_gufunc_kwargs`` parameter. It will be removed as direct parameter in a future version.\n",
      "  ds_out = xr.apply_ufunc(\n",
      "/srv/conda/envs/notebook/lib/python3.8/site-packages/xesmf/frontend.py:473: FutureWarning: ``output_sizes`` should be given in the ``dask_gufunc_kwargs`` parameter. It will be removed as direct parameter in a future version.\n",
      "  ds_out = xr.apply_ufunc(\n",
      "/srv/conda/envs/notebook/lib/python3.8/site-packages/xesmf/frontend.py:473: FutureWarning: ``output_sizes`` should be given in the ``dask_gufunc_kwargs`` parameter. It will be removed as direct parameter in a future version.\n",
      "  ds_out = xr.apply_ufunc(\n"
     ]
    }
   ],
   "source": [
    "import xesmf as xe # I use xesmf to regrid from the ocean curvelinear to lat/lon grid\n",
    "\n",
    "#xesmf doesn't like it when I define the grid from the dataset, so I like to explicitly define input and output grids\n",
    "# For a curvelinear grid, we need both lat/lon and lat/lon bounds\n",
    "\n",
    "lonO=theta_eq.longitude\n",
    "latO=theta_eq.latitude\n",
    "#lonO_b=theta_eq.x_bnds\n",
    "#latO_b=theta_eq.y_bnds\n",
    "\n",
    "\n",
    "grid_in = {'lon': lonO, 'lat': latO} \n",
    "\n",
    "grid_out = xr.Dataset({'lat': (['lat'], np.arange(-5, 5, 1.0)),\n",
    "                     'lon': (['lon'], np.arange(0, 359, 1)),})\n",
    "\n",
    "\n",
    "regridder = xe.Regridder(grid_in, grid_out, 'bilinear')\n",
    "\n",
    "\n",
    "thetao_regrid = regridder(theta_eq)\n",
    "#thetao_deep_regrid = regridder(theta_pi_deep)\n",
    "uo_regrid = regridder(uo_eq) \n",
    "vo_regrid = regridder(vo_eq)  \n",
    "wo_regrid = regridder(wo_eq)  "
   ]
  },
  {
   "cell_type": "code",
   "execution_count": null,
   "id": "absolute-disposal",
   "metadata": {},
   "outputs": [],
   "source": [
    "#theta_eq.to_netcdf('theta_eq_'+'IPSL-CM6A-LR'+'_ens1.nc')\n",
    "#theta_eq.load()\n",
    "#theta_eq\n",
    "theta_rg_eq=thetao_regrid.sel(lat=slice(-5,5)).mean('lat')\n",
    "theta_rg_eq.load()\n",
    "theta_rg_eq.to_netcdf('theta_eq_'+'HadGEM3-GC31-LL'+'_control.nc')"
   ]
  },
  {
   "cell_type": "code",
   "execution_count": 22,
   "id": "black-crime",
   "metadata": {},
   "outputs": [
    {
     "name": "stderr",
     "output_type": "stream",
     "text": [
      "distributed.client - ERROR - Failed to reconnect to scheduler after 120.00 seconds, closing client\n",
      "_GatheringFuture exception was never retrieved\n",
      "future: <_GatheringFuture finished exception=CancelledError()>\n",
      "asyncio.exceptions.CancelledError\n",
      "Exception in callback None()\n",
      "handle: <Handle cancelled>\n",
      "Traceback (most recent call last):\n",
      "  File \"/srv/conda/envs/notebook/lib/python3.8/site-packages/tornado/iostream.py\", line 1391, in _do_ssl_handshake\n",
      "    self.socket.do_handshake()\n",
      "  File \"/srv/conda/envs/notebook/lib/python3.8/ssl.py\", line 1309, in do_handshake\n",
      "    self._sslobj.do_handshake()\n",
      "ssl.SSLCertVerificationError: [SSL: CERTIFICATE_VERIFY_FAILED] certificate verify failed: self signed certificate (_ssl.c:1124)\n",
      "\n",
      "During handling of the above exception, another exception occurred:\n",
      "\n",
      "Traceback (most recent call last):\n",
      "  File \"/srv/conda/envs/notebook/lib/python3.8/asyncio/events.py\", line 81, in _run\n",
      "    self._context.run(self._callback, *self._args)\n",
      "  File \"/srv/conda/envs/notebook/lib/python3.8/site-packages/tornado/platform/asyncio.py\", line 189, in _handle_events\n",
      "    handler_func(fileobj, events)\n",
      "  File \"/srv/conda/envs/notebook/lib/python3.8/site-packages/tornado/iostream.py\", line 696, in _handle_events\n",
      "    self._handle_read()\n",
      "  File \"/srv/conda/envs/notebook/lib/python3.8/site-packages/tornado/iostream.py\", line 1478, in _handle_read\n",
      "    self._do_ssl_handshake()\n",
      "  File \"/srv/conda/envs/notebook/lib/python3.8/site-packages/tornado/iostream.py\", line 1409, in _do_ssl_handshake\n",
      "    return self.close(exc_info=err)\n",
      "  File \"/srv/conda/envs/notebook/lib/python3.8/site-packages/tornado/iostream.py\", line 611, in close\n",
      "    self._signal_closed()\n",
      "  File \"/srv/conda/envs/notebook/lib/python3.8/site-packages/tornado/iostream.py\", line 641, in _signal_closed\n",
      "    self._ssl_connect_future.exception()\n",
      "asyncio.exceptions.CancelledError\n",
      "Exception in callback None()\n",
      "handle: <Handle cancelled>\n",
      "Traceback (most recent call last):\n",
      "  File \"/srv/conda/envs/notebook/lib/python3.8/site-packages/tornado/iostream.py\", line 1391, in _do_ssl_handshake\n",
      "    self.socket.do_handshake()\n",
      "  File \"/srv/conda/envs/notebook/lib/python3.8/ssl.py\", line 1309, in do_handshake\n",
      "    self._sslobj.do_handshake()\n",
      "ssl.SSLCertVerificationError: [SSL: CERTIFICATE_VERIFY_FAILED] certificate verify failed: self signed certificate (_ssl.c:1124)\n",
      "\n",
      "During handling of the above exception, another exception occurred:\n",
      "\n",
      "Traceback (most recent call last):\n",
      "  File \"/srv/conda/envs/notebook/lib/python3.8/asyncio/events.py\", line 81, in _run\n",
      "    self._context.run(self._callback, *self._args)\n",
      "  File \"/srv/conda/envs/notebook/lib/python3.8/site-packages/tornado/platform/asyncio.py\", line 189, in _handle_events\n",
      "    handler_func(fileobj, events)\n",
      "  File \"/srv/conda/envs/notebook/lib/python3.8/site-packages/tornado/iostream.py\", line 696, in _handle_events\n",
      "    self._handle_read()\n",
      "  File \"/srv/conda/envs/notebook/lib/python3.8/site-packages/tornado/iostream.py\", line 1478, in _handle_read\n",
      "    self._do_ssl_handshake()\n",
      "  File \"/srv/conda/envs/notebook/lib/python3.8/site-packages/tornado/iostream.py\", line 1409, in _do_ssl_handshake\n",
      "    return self.close(exc_info=err)\n",
      "  File \"/srv/conda/envs/notebook/lib/python3.8/site-packages/tornado/iostream.py\", line 611, in close\n",
      "    self._signal_closed()\n",
      "  File \"/srv/conda/envs/notebook/lib/python3.8/site-packages/tornado/iostream.py\", line 641, in _signal_closed\n",
      "    self._ssl_connect_future.exception()\n",
      "asyncio.exceptions.CancelledError\n",
      "Exception in callback None()\n",
      "handle: <Handle cancelled>\n",
      "Traceback (most recent call last):\n",
      "  File \"/srv/conda/envs/notebook/lib/python3.8/site-packages/tornado/iostream.py\", line 1391, in _do_ssl_handshake\n",
      "    self.socket.do_handshake()\n",
      "  File \"/srv/conda/envs/notebook/lib/python3.8/ssl.py\", line 1309, in do_handshake\n",
      "    self._sslobj.do_handshake()\n",
      "ssl.SSLCertVerificationError: [SSL: CERTIFICATE_VERIFY_FAILED] certificate verify failed: self signed certificate (_ssl.c:1124)\n",
      "\n",
      "During handling of the above exception, another exception occurred:\n",
      "\n",
      "Traceback (most recent call last):\n",
      "  File \"/srv/conda/envs/notebook/lib/python3.8/asyncio/events.py\", line 81, in _run\n",
      "    self._context.run(self._callback, *self._args)\n",
      "  File \"/srv/conda/envs/notebook/lib/python3.8/site-packages/tornado/platform/asyncio.py\", line 189, in _handle_events\n",
      "    handler_func(fileobj, events)\n",
      "  File \"/srv/conda/envs/notebook/lib/python3.8/site-packages/tornado/iostream.py\", line 696, in _handle_events\n",
      "    self._handle_read()\n",
      "  File \"/srv/conda/envs/notebook/lib/python3.8/site-packages/tornado/iostream.py\", line 1478, in _handle_read\n",
      "    self._do_ssl_handshake()\n",
      "  File \"/srv/conda/envs/notebook/lib/python3.8/site-packages/tornado/iostream.py\", line 1409, in _do_ssl_handshake\n",
      "    return self.close(exc_info=err)\n",
      "  File \"/srv/conda/envs/notebook/lib/python3.8/site-packages/tornado/iostream.py\", line 611, in close\n",
      "    self._signal_closed()\n",
      "  File \"/srv/conda/envs/notebook/lib/python3.8/site-packages/tornado/iostream.py\", line 641, in _signal_closed\n",
      "    self._ssl_connect_future.exception()\n",
      "asyncio.exceptions.CancelledError\n",
      "Exception in callback None()\n",
      "handle: <Handle cancelled>\n",
      "Traceback (most recent call last):\n",
      "  File \"/srv/conda/envs/notebook/lib/python3.8/site-packages/tornado/iostream.py\", line 1391, in _do_ssl_handshake\n",
      "    self.socket.do_handshake()\n",
      "  File \"/srv/conda/envs/notebook/lib/python3.8/ssl.py\", line 1309, in do_handshake\n",
      "    self._sslobj.do_handshake()\n",
      "ssl.SSLCertVerificationError: [SSL: CERTIFICATE_VERIFY_FAILED] certificate verify failed: self signed certificate (_ssl.c:1124)\n",
      "\n",
      "During handling of the above exception, another exception occurred:\n",
      "\n",
      "Traceback (most recent call last):\n",
      "  File \"/srv/conda/envs/notebook/lib/python3.8/asyncio/events.py\", line 81, in _run\n",
      "    self._context.run(self._callback, *self._args)\n",
      "  File \"/srv/conda/envs/notebook/lib/python3.8/site-packages/tornado/platform/asyncio.py\", line 189, in _handle_events\n",
      "    handler_func(fileobj, events)\n",
      "  File \"/srv/conda/envs/notebook/lib/python3.8/site-packages/tornado/iostream.py\", line 696, in _handle_events\n",
      "    self._handle_read()\n",
      "  File \"/srv/conda/envs/notebook/lib/python3.8/site-packages/tornado/iostream.py\", line 1478, in _handle_read\n",
      "    self._do_ssl_handshake()\n",
      "  File \"/srv/conda/envs/notebook/lib/python3.8/site-packages/tornado/iostream.py\", line 1409, in _do_ssl_handshake\n",
      "    return self.close(exc_info=err)\n",
      "  File \"/srv/conda/envs/notebook/lib/python3.8/site-packages/tornado/iostream.py\", line 611, in close\n",
      "    self._signal_closed()\n",
      "  File \"/srv/conda/envs/notebook/lib/python3.8/site-packages/tornado/iostream.py\", line 641, in _signal_closed\n",
      "    self._ssl_connect_future.exception()\n",
      "asyncio.exceptions.CancelledError\n",
      "Exception in callback None()\n",
      "handle: <Handle cancelled>\n",
      "Traceback (most recent call last):\n",
      "  File \"/srv/conda/envs/notebook/lib/python3.8/site-packages/tornado/iostream.py\", line 1391, in _do_ssl_handshake\n",
      "    self.socket.do_handshake()\n",
      "  File \"/srv/conda/envs/notebook/lib/python3.8/ssl.py\", line 1309, in do_handshake\n",
      "    self._sslobj.do_handshake()\n",
      "ssl.SSLCertVerificationError: [SSL: CERTIFICATE_VERIFY_FAILED] certificate verify failed: self signed certificate (_ssl.c:1124)\n",
      "\n",
      "During handling of the above exception, another exception occurred:\n",
      "\n",
      "Traceback (most recent call last):\n",
      "  File \"/srv/conda/envs/notebook/lib/python3.8/asyncio/events.py\", line 81, in _run\n",
      "    self._context.run(self._callback, *self._args)\n",
      "  File \"/srv/conda/envs/notebook/lib/python3.8/site-packages/tornado/platform/asyncio.py\", line 189, in _handle_events\n",
      "    handler_func(fileobj, events)\n",
      "  File \"/srv/conda/envs/notebook/lib/python3.8/site-packages/tornado/iostream.py\", line 696, in _handle_events\n",
      "    self._handle_read()\n",
      "  File \"/srv/conda/envs/notebook/lib/python3.8/site-packages/tornado/iostream.py\", line 1478, in _handle_read\n",
      "    self._do_ssl_handshake()\n",
      "  File \"/srv/conda/envs/notebook/lib/python3.8/site-packages/tornado/iostream.py\", line 1409, in _do_ssl_handshake\n",
      "    return self.close(exc_info=err)\n",
      "  File \"/srv/conda/envs/notebook/lib/python3.8/site-packages/tornado/iostream.py\", line 611, in close\n",
      "    self._signal_closed()\n",
      "  File \"/srv/conda/envs/notebook/lib/python3.8/site-packages/tornado/iostream.py\", line 641, in _signal_closed\n",
      "    self._ssl_connect_future.exception()\n",
      "asyncio.exceptions.CancelledError\n",
      "Exception in callback None()\n",
      "handle: <Handle cancelled>\n",
      "Traceback (most recent call last):\n",
      "  File \"/srv/conda/envs/notebook/lib/python3.8/site-packages/tornado/iostream.py\", line 1391, in _do_ssl_handshake\n",
      "    self.socket.do_handshake()\n",
      "  File \"/srv/conda/envs/notebook/lib/python3.8/ssl.py\", line 1309, in do_handshake\n",
      "    self._sslobj.do_handshake()\n",
      "ssl.SSLCertVerificationError: [SSL: CERTIFICATE_VERIFY_FAILED] certificate verify failed: self signed certificate (_ssl.c:1124)\n",
      "\n",
      "During handling of the above exception, another exception occurred:\n",
      "\n",
      "Traceback (most recent call last):\n",
      "  File \"/srv/conda/envs/notebook/lib/python3.8/asyncio/events.py\", line 81, in _run\n",
      "    self._context.run(self._callback, *self._args)\n",
      "  File \"/srv/conda/envs/notebook/lib/python3.8/site-packages/tornado/platform/asyncio.py\", line 189, in _handle_events\n",
      "    handler_func(fileobj, events)\n",
      "  File \"/srv/conda/envs/notebook/lib/python3.8/site-packages/tornado/iostream.py\", line 696, in _handle_events\n",
      "    self._handle_read()\n",
      "  File \"/srv/conda/envs/notebook/lib/python3.8/site-packages/tornado/iostream.py\", line 1478, in _handle_read\n",
      "    self._do_ssl_handshake()\n",
      "  File \"/srv/conda/envs/notebook/lib/python3.8/site-packages/tornado/iostream.py\", line 1409, in _do_ssl_handshake\n",
      "    return self.close(exc_info=err)\n",
      "  File \"/srv/conda/envs/notebook/lib/python3.8/site-packages/tornado/iostream.py\", line 611, in close\n",
      "    self._signal_closed()\n",
      "  File \"/srv/conda/envs/notebook/lib/python3.8/site-packages/tornado/iostream.py\", line 641, in _signal_closed\n",
      "    self._ssl_connect_future.exception()\n",
      "asyncio.exceptions.CancelledError\n",
      "Exception in callback None()\n",
      "handle: <Handle cancelled>\n",
      "Traceback (most recent call last):\n",
      "  File \"/srv/conda/envs/notebook/lib/python3.8/site-packages/tornado/iostream.py\", line 1391, in _do_ssl_handshake\n",
      "    self.socket.do_handshake()\n",
      "  File \"/srv/conda/envs/notebook/lib/python3.8/ssl.py\", line 1309, in do_handshake\n",
      "    self._sslobj.do_handshake()\n",
      "ssl.SSLCertVerificationError: [SSL: CERTIFICATE_VERIFY_FAILED] certificate verify failed: self signed certificate (_ssl.c:1124)\n",
      "\n",
      "During handling of the above exception, another exception occurred:\n",
      "\n",
      "Traceback (most recent call last):\n",
      "  File \"/srv/conda/envs/notebook/lib/python3.8/asyncio/events.py\", line 81, in _run\n",
      "    self._context.run(self._callback, *self._args)\n",
      "  File \"/srv/conda/envs/notebook/lib/python3.8/site-packages/tornado/platform/asyncio.py\", line 189, in _handle_events\n",
      "    handler_func(fileobj, events)\n",
      "  File \"/srv/conda/envs/notebook/lib/python3.8/site-packages/tornado/iostream.py\", line 696, in _handle_events\n",
      "    self._handle_read()\n",
      "  File \"/srv/conda/envs/notebook/lib/python3.8/site-packages/tornado/iostream.py\", line 1478, in _handle_read\n",
      "    self._do_ssl_handshake()\n",
      "  File \"/srv/conda/envs/notebook/lib/python3.8/site-packages/tornado/iostream.py\", line 1409, in _do_ssl_handshake\n",
      "    return self.close(exc_info=err)\n",
      "  File \"/srv/conda/envs/notebook/lib/python3.8/site-packages/tornado/iostream.py\", line 611, in close\n",
      "    self._signal_closed()\n",
      "  File \"/srv/conda/envs/notebook/lib/python3.8/site-packages/tornado/iostream.py\", line 641, in _signal_closed\n",
      "    self._ssl_connect_future.exception()\n",
      "asyncio.exceptions.CancelledError\n",
      "Exception in callback None()\n",
      "handle: <Handle cancelled>\n",
      "Traceback (most recent call last):\n",
      "  File \"/srv/conda/envs/notebook/lib/python3.8/site-packages/tornado/iostream.py\", line 1391, in _do_ssl_handshake\n",
      "    self.socket.do_handshake()\n",
      "  File \"/srv/conda/envs/notebook/lib/python3.8/ssl.py\", line 1309, in do_handshake\n",
      "    self._sslobj.do_handshake()\n",
      "ssl.SSLCertVerificationError: [SSL: CERTIFICATE_VERIFY_FAILED] certificate verify failed: self signed certificate (_ssl.c:1124)\n",
      "\n",
      "During handling of the above exception, another exception occurred:\n",
      "\n",
      "Traceback (most recent call last):\n",
      "  File \"/srv/conda/envs/notebook/lib/python3.8/asyncio/events.py\", line 81, in _run\n",
      "    self._context.run(self._callback, *self._args)\n",
      "  File \"/srv/conda/envs/notebook/lib/python3.8/site-packages/tornado/platform/asyncio.py\", line 189, in _handle_events\n",
      "    handler_func(fileobj, events)\n",
      "  File \"/srv/conda/envs/notebook/lib/python3.8/site-packages/tornado/iostream.py\", line 696, in _handle_events\n",
      "    self._handle_read()\n",
      "  File \"/srv/conda/envs/notebook/lib/python3.8/site-packages/tornado/iostream.py\", line 1478, in _handle_read\n",
      "    self._do_ssl_handshake()\n",
      "  File \"/srv/conda/envs/notebook/lib/python3.8/site-packages/tornado/iostream.py\", line 1409, in _do_ssl_handshake\n",
      "    return self.close(exc_info=err)\n",
      "  File \"/srv/conda/envs/notebook/lib/python3.8/site-packages/tornado/iostream.py\", line 611, in close\n",
      "    self._signal_closed()\n",
      "  File \"/srv/conda/envs/notebook/lib/python3.8/site-packages/tornado/iostream.py\", line 641, in _signal_closed\n",
      "    self._ssl_connect_future.exception()\n",
      "asyncio.exceptions.CancelledError\n",
      "Exception in callback None()\n",
      "handle: <Handle cancelled>\n",
      "Traceback (most recent call last):\n",
      "  File \"/srv/conda/envs/notebook/lib/python3.8/site-packages/tornado/iostream.py\", line 1391, in _do_ssl_handshake\n",
      "    self.socket.do_handshake()\n",
      "  File \"/srv/conda/envs/notebook/lib/python3.8/ssl.py\", line 1309, in do_handshake\n",
      "    self._sslobj.do_handshake()\n",
      "ssl.SSLCertVerificationError: [SSL: CERTIFICATE_VERIFY_FAILED] certificate verify failed: self signed certificate (_ssl.c:1124)\n",
      "\n",
      "During handling of the above exception, another exception occurred:\n",
      "\n",
      "Traceback (most recent call last):\n",
      "  File \"/srv/conda/envs/notebook/lib/python3.8/asyncio/events.py\", line 81, in _run\n",
      "    self._context.run(self._callback, *self._args)\n",
      "  File \"/srv/conda/envs/notebook/lib/python3.8/site-packages/tornado/platform/asyncio.py\", line 189, in _handle_events\n",
      "    handler_func(fileobj, events)\n",
      "  File \"/srv/conda/envs/notebook/lib/python3.8/site-packages/tornado/iostream.py\", line 696, in _handle_events\n",
      "    self._handle_read()\n",
      "  File \"/srv/conda/envs/notebook/lib/python3.8/site-packages/tornado/iostream.py\", line 1478, in _handle_read\n",
      "    self._do_ssl_handshake()\n",
      "  File \"/srv/conda/envs/notebook/lib/python3.8/site-packages/tornado/iostream.py\", line 1409, in _do_ssl_handshake\n",
      "    return self.close(exc_info=err)\n",
      "  File \"/srv/conda/envs/notebook/lib/python3.8/site-packages/tornado/iostream.py\", line 611, in close\n",
      "    self._signal_closed()\n",
      "  File \"/srv/conda/envs/notebook/lib/python3.8/site-packages/tornado/iostream.py\", line 641, in _signal_closed\n",
      "    self._ssl_connect_future.exception()\n",
      "asyncio.exceptions.CancelledError\n",
      "Exception in callback None()\n",
      "handle: <Handle cancelled>\n",
      "Traceback (most recent call last):\n",
      "  File \"/srv/conda/envs/notebook/lib/python3.8/site-packages/tornado/iostream.py\", line 1391, in _do_ssl_handshake\n",
      "    self.socket.do_handshake()\n",
      "  File \"/srv/conda/envs/notebook/lib/python3.8/ssl.py\", line 1309, in do_handshake\n",
      "    self._sslobj.do_handshake()\n",
      "ssl.SSLCertVerificationError: [SSL: CERTIFICATE_VERIFY_FAILED] certificate verify failed: self signed certificate (_ssl.c:1124)\n",
      "\n",
      "During handling of the above exception, another exception occurred:\n",
      "\n",
      "Traceback (most recent call last):\n",
      "  File \"/srv/conda/envs/notebook/lib/python3.8/asyncio/events.py\", line 81, in _run\n",
      "    self._context.run(self._callback, *self._args)\n",
      "  File \"/srv/conda/envs/notebook/lib/python3.8/site-packages/tornado/platform/asyncio.py\", line 189, in _handle_events\n",
      "    handler_func(fileobj, events)\n",
      "  File \"/srv/conda/envs/notebook/lib/python3.8/site-packages/tornado/iostream.py\", line 696, in _handle_events\n",
      "    self._handle_read()\n",
      "  File \"/srv/conda/envs/notebook/lib/python3.8/site-packages/tornado/iostream.py\", line 1478, in _handle_read\n",
      "    self._do_ssl_handshake()\n",
      "  File \"/srv/conda/envs/notebook/lib/python3.8/site-packages/tornado/iostream.py\", line 1409, in _do_ssl_handshake\n",
      "    return self.close(exc_info=err)\n",
      "  File \"/srv/conda/envs/notebook/lib/python3.8/site-packages/tornado/iostream.py\", line 611, in close\n",
      "    self._signal_closed()\n",
      "  File \"/srv/conda/envs/notebook/lib/python3.8/site-packages/tornado/iostream.py\", line 641, in _signal_closed\n",
      "    self._ssl_connect_future.exception()\n",
      "asyncio.exceptions.CancelledError\n",
      "Exception in callback None()\n",
      "handle: <Handle cancelled>\n",
      "Traceback (most recent call last):\n",
      "  File \"/srv/conda/envs/notebook/lib/python3.8/site-packages/tornado/iostream.py\", line 1391, in _do_ssl_handshake\n",
      "    self.socket.do_handshake()\n",
      "  File \"/srv/conda/envs/notebook/lib/python3.8/ssl.py\", line 1309, in do_handshake\n",
      "    self._sslobj.do_handshake()\n",
      "ssl.SSLCertVerificationError: [SSL: CERTIFICATE_VERIFY_FAILED] certificate verify failed: self signed certificate (_ssl.c:1124)\n",
      "\n",
      "During handling of the above exception, another exception occurred:\n",
      "\n",
      "Traceback (most recent call last):\n",
      "  File \"/srv/conda/envs/notebook/lib/python3.8/asyncio/events.py\", line 81, in _run\n",
      "    self._context.run(self._callback, *self._args)\n",
      "  File \"/srv/conda/envs/notebook/lib/python3.8/site-packages/tornado/platform/asyncio.py\", line 189, in _handle_events\n",
      "    handler_func(fileobj, events)\n",
      "  File \"/srv/conda/envs/notebook/lib/python3.8/site-packages/tornado/iostream.py\", line 696, in _handle_events\n",
      "    self._handle_read()\n",
      "  File \"/srv/conda/envs/notebook/lib/python3.8/site-packages/tornado/iostream.py\", line 1478, in _handle_read\n",
      "    self._do_ssl_handshake()\n",
      "  File \"/srv/conda/envs/notebook/lib/python3.8/site-packages/tornado/iostream.py\", line 1409, in _do_ssl_handshake\n",
      "    return self.close(exc_info=err)\n",
      "  File \"/srv/conda/envs/notebook/lib/python3.8/site-packages/tornado/iostream.py\", line 611, in close\n",
      "    self._signal_closed()\n",
      "  File \"/srv/conda/envs/notebook/lib/python3.8/site-packages/tornado/iostream.py\", line 641, in _signal_closed\n",
      "    self._ssl_connect_future.exception()\n",
      "asyncio.exceptions.CancelledError\n",
      "Exception in callback None()\n",
      "handle: <Handle cancelled>\n",
      "Traceback (most recent call last):\n",
      "  File \"/srv/conda/envs/notebook/lib/python3.8/site-packages/tornado/iostream.py\", line 1391, in _do_ssl_handshake\n",
      "    self.socket.do_handshake()\n",
      "  File \"/srv/conda/envs/notebook/lib/python3.8/ssl.py\", line 1309, in do_handshake\n",
      "    self._sslobj.do_handshake()\n",
      "ssl.SSLCertVerificationError: [SSL: CERTIFICATE_VERIFY_FAILED] certificate verify failed: self signed certificate (_ssl.c:1124)\n",
      "\n",
      "During handling of the above exception, another exception occurred:\n",
      "\n",
      "Traceback (most recent call last):\n",
      "  File \"/srv/conda/envs/notebook/lib/python3.8/asyncio/events.py\", line 81, in _run\n",
      "    self._context.run(self._callback, *self._args)\n",
      "  File \"/srv/conda/envs/notebook/lib/python3.8/site-packages/tornado/platform/asyncio.py\", line 189, in _handle_events\n",
      "    handler_func(fileobj, events)\n",
      "  File \"/srv/conda/envs/notebook/lib/python3.8/site-packages/tornado/iostream.py\", line 696, in _handle_events\n",
      "    self._handle_read()\n",
      "  File \"/srv/conda/envs/notebook/lib/python3.8/site-packages/tornado/iostream.py\", line 1478, in _handle_read\n",
      "    self._do_ssl_handshake()\n",
      "  File \"/srv/conda/envs/notebook/lib/python3.8/site-packages/tornado/iostream.py\", line 1409, in _do_ssl_handshake\n",
      "    return self.close(exc_info=err)\n",
      "  File \"/srv/conda/envs/notebook/lib/python3.8/site-packages/tornado/iostream.py\", line 611, in close\n",
      "    self._signal_closed()\n",
      "  File \"/srv/conda/envs/notebook/lib/python3.8/site-packages/tornado/iostream.py\", line 641, in _signal_closed\n",
      "    self._ssl_connect_future.exception()\n",
      "asyncio.exceptions.CancelledError\n",
      "Exception in callback None()\n",
      "handle: <Handle cancelled>\n",
      "Traceback (most recent call last):\n",
      "  File \"/srv/conda/envs/notebook/lib/python3.8/site-packages/tornado/iostream.py\", line 1391, in _do_ssl_handshake\n",
      "    self.socket.do_handshake()\n",
      "  File \"/srv/conda/envs/notebook/lib/python3.8/ssl.py\", line 1309, in do_handshake\n",
      "    self._sslobj.do_handshake()\n",
      "ssl.SSLCertVerificationError: [SSL: CERTIFICATE_VERIFY_FAILED] certificate verify failed: self signed certificate (_ssl.c:1124)\n",
      "\n",
      "During handling of the above exception, another exception occurred:\n",
      "\n",
      "Traceback (most recent call last):\n",
      "  File \"/srv/conda/envs/notebook/lib/python3.8/asyncio/events.py\", line 81, in _run\n",
      "    self._context.run(self._callback, *self._args)\n",
      "  File \"/srv/conda/envs/notebook/lib/python3.8/site-packages/tornado/platform/asyncio.py\", line 189, in _handle_events\n",
      "    handler_func(fileobj, events)\n",
      "  File \"/srv/conda/envs/notebook/lib/python3.8/site-packages/tornado/iostream.py\", line 696, in _handle_events\n",
      "    self._handle_read()\n",
      "  File \"/srv/conda/envs/notebook/lib/python3.8/site-packages/tornado/iostream.py\", line 1478, in _handle_read\n",
      "    self._do_ssl_handshake()\n",
      "  File \"/srv/conda/envs/notebook/lib/python3.8/site-packages/tornado/iostream.py\", line 1409, in _do_ssl_handshake\n",
      "    return self.close(exc_info=err)\n",
      "  File \"/srv/conda/envs/notebook/lib/python3.8/site-packages/tornado/iostream.py\", line 611, in close\n",
      "    self._signal_closed()\n",
      "  File \"/srv/conda/envs/notebook/lib/python3.8/site-packages/tornado/iostream.py\", line 641, in _signal_closed\n",
      "    self._ssl_connect_future.exception()\n",
      "asyncio.exceptions.CancelledError\n",
      "Exception in callback None()\n",
      "handle: <Handle cancelled>\n",
      "Traceback (most recent call last):\n",
      "  File \"/srv/conda/envs/notebook/lib/python3.8/site-packages/tornado/iostream.py\", line 1391, in _do_ssl_handshake\n",
      "    self.socket.do_handshake()\n",
      "  File \"/srv/conda/envs/notebook/lib/python3.8/ssl.py\", line 1309, in do_handshake\n",
      "    self._sslobj.do_handshake()\n",
      "ssl.SSLCertVerificationError: [SSL: CERTIFICATE_VERIFY_FAILED] certificate verify failed: self signed certificate (_ssl.c:1124)\n",
      "\n",
      "During handling of the above exception, another exception occurred:\n",
      "\n",
      "Traceback (most recent call last):\n",
      "  File \"/srv/conda/envs/notebook/lib/python3.8/asyncio/events.py\", line 81, in _run\n",
      "    self._context.run(self._callback, *self._args)\n",
      "  File \"/srv/conda/envs/notebook/lib/python3.8/site-packages/tornado/platform/asyncio.py\", line 189, in _handle_events\n",
      "    handler_func(fileobj, events)\n",
      "  File \"/srv/conda/envs/notebook/lib/python3.8/site-packages/tornado/iostream.py\", line 696, in _handle_events\n",
      "    self._handle_read()\n",
      "  File \"/srv/conda/envs/notebook/lib/python3.8/site-packages/tornado/iostream.py\", line 1478, in _handle_read\n",
      "    self._do_ssl_handshake()\n",
      "  File \"/srv/conda/envs/notebook/lib/python3.8/site-packages/tornado/iostream.py\", line 1409, in _do_ssl_handshake\n",
      "    return self.close(exc_info=err)\n",
      "  File \"/srv/conda/envs/notebook/lib/python3.8/site-packages/tornado/iostream.py\", line 611, in close\n",
      "    self._signal_closed()\n",
      "  File \"/srv/conda/envs/notebook/lib/python3.8/site-packages/tornado/iostream.py\", line 641, in _signal_closed\n",
      "    self._ssl_connect_future.exception()\n",
      "asyncio.exceptions.CancelledError\n",
      "Exception in callback None()\n",
      "handle: <Handle cancelled>\n",
      "Traceback (most recent call last):\n",
      "  File \"/srv/conda/envs/notebook/lib/python3.8/site-packages/tornado/iostream.py\", line 1391, in _do_ssl_handshake\n",
      "    self.socket.do_handshake()\n",
      "  File \"/srv/conda/envs/notebook/lib/python3.8/ssl.py\", line 1309, in do_handshake\n",
      "    self._sslobj.do_handshake()\n",
      "ssl.SSLCertVerificationError: [SSL: CERTIFICATE_VERIFY_FAILED] certificate verify failed: self signed certificate (_ssl.c:1124)\n",
      "\n",
      "During handling of the above exception, another exception occurred:\n",
      "\n",
      "Traceback (most recent call last):\n",
      "  File \"/srv/conda/envs/notebook/lib/python3.8/asyncio/events.py\", line 81, in _run\n",
      "    self._context.run(self._callback, *self._args)\n",
      "  File \"/srv/conda/envs/notebook/lib/python3.8/site-packages/tornado/platform/asyncio.py\", line 189, in _handle_events\n",
      "    handler_func(fileobj, events)\n",
      "  File \"/srv/conda/envs/notebook/lib/python3.8/site-packages/tornado/iostream.py\", line 696, in _handle_events\n",
      "    self._handle_read()\n",
      "  File \"/srv/conda/envs/notebook/lib/python3.8/site-packages/tornado/iostream.py\", line 1478, in _handle_read\n",
      "    self._do_ssl_handshake()\n",
      "  File \"/srv/conda/envs/notebook/lib/python3.8/site-packages/tornado/iostream.py\", line 1409, in _do_ssl_handshake\n",
      "    return self.close(exc_info=err)\n",
      "  File \"/srv/conda/envs/notebook/lib/python3.8/site-packages/tornado/iostream.py\", line 611, in close\n",
      "    self._signal_closed()\n",
      "  File \"/srv/conda/envs/notebook/lib/python3.8/site-packages/tornado/iostream.py\", line 641, in _signal_closed\n",
      "    self._ssl_connect_future.exception()\n",
      "asyncio.exceptions.CancelledError\n",
      "Exception in callback None()\n",
      "handle: <Handle cancelled>\n",
      "Traceback (most recent call last):\n",
      "  File \"/srv/conda/envs/notebook/lib/python3.8/site-packages/tornado/iostream.py\", line 1391, in _do_ssl_handshake\n",
      "    self.socket.do_handshake()\n",
      "  File \"/srv/conda/envs/notebook/lib/python3.8/ssl.py\", line 1309, in do_handshake\n",
      "    self._sslobj.do_handshake()\n",
      "ssl.SSLCertVerificationError: [SSL: CERTIFICATE_VERIFY_FAILED] certificate verify failed: self signed certificate (_ssl.c:1124)\n",
      "\n",
      "During handling of the above exception, another exception occurred:\n",
      "\n",
      "Traceback (most recent call last):\n",
      "  File \"/srv/conda/envs/notebook/lib/python3.8/asyncio/events.py\", line 81, in _run\n",
      "    self._context.run(self._callback, *self._args)\n",
      "  File \"/srv/conda/envs/notebook/lib/python3.8/site-packages/tornado/platform/asyncio.py\", line 189, in _handle_events\n",
      "    handler_func(fileobj, events)\n",
      "  File \"/srv/conda/envs/notebook/lib/python3.8/site-packages/tornado/iostream.py\", line 696, in _handle_events\n",
      "    self._handle_read()\n",
      "  File \"/srv/conda/envs/notebook/lib/python3.8/site-packages/tornado/iostream.py\", line 1478, in _handle_read\n",
      "    self._do_ssl_handshake()\n",
      "  File \"/srv/conda/envs/notebook/lib/python3.8/site-packages/tornado/iostream.py\", line 1409, in _do_ssl_handshake\n",
      "    return self.close(exc_info=err)\n",
      "  File \"/srv/conda/envs/notebook/lib/python3.8/site-packages/tornado/iostream.py\", line 611, in close\n",
      "    self._signal_closed()\n",
      "  File \"/srv/conda/envs/notebook/lib/python3.8/site-packages/tornado/iostream.py\", line 641, in _signal_closed\n",
      "    self._ssl_connect_future.exception()\n",
      "asyncio.exceptions.CancelledError\n",
      "Exception in callback None()\n",
      "handle: <Handle cancelled>\n",
      "Traceback (most recent call last):\n",
      "  File \"/srv/conda/envs/notebook/lib/python3.8/site-packages/tornado/iostream.py\", line 1391, in _do_ssl_handshake\n",
      "    self.socket.do_handshake()\n",
      "  File \"/srv/conda/envs/notebook/lib/python3.8/ssl.py\", line 1309, in do_handshake\n",
      "    self._sslobj.do_handshake()\n",
      "ssl.SSLCertVerificationError: [SSL: CERTIFICATE_VERIFY_FAILED] certificate verify failed: self signed certificate (_ssl.c:1124)\n",
      "\n",
      "During handling of the above exception, another exception occurred:\n",
      "\n",
      "Traceback (most recent call last):\n",
      "  File \"/srv/conda/envs/notebook/lib/python3.8/asyncio/events.py\", line 81, in _run\n",
      "    self._context.run(self._callback, *self._args)\n",
      "  File \"/srv/conda/envs/notebook/lib/python3.8/site-packages/tornado/platform/asyncio.py\", line 189, in _handle_events\n",
      "    handler_func(fileobj, events)\n",
      "  File \"/srv/conda/envs/notebook/lib/python3.8/site-packages/tornado/iostream.py\", line 696, in _handle_events\n",
      "    self._handle_read()\n",
      "  File \"/srv/conda/envs/notebook/lib/python3.8/site-packages/tornado/iostream.py\", line 1478, in _handle_read\n",
      "    self._do_ssl_handshake()\n",
      "  File \"/srv/conda/envs/notebook/lib/python3.8/site-packages/tornado/iostream.py\", line 1409, in _do_ssl_handshake\n",
      "    return self.close(exc_info=err)\n",
      "  File \"/srv/conda/envs/notebook/lib/python3.8/site-packages/tornado/iostream.py\", line 611, in close\n",
      "    self._signal_closed()\n",
      "  File \"/srv/conda/envs/notebook/lib/python3.8/site-packages/tornado/iostream.py\", line 641, in _signal_closed\n",
      "    self._ssl_connect_future.exception()\n",
      "asyncio.exceptions.CancelledError\n",
      "Exception in callback None()\n",
      "handle: <Handle cancelled>\n",
      "Traceback (most recent call last):\n",
      "  File \"/srv/conda/envs/notebook/lib/python3.8/site-packages/tornado/iostream.py\", line 1391, in _do_ssl_handshake\n",
      "    self.socket.do_handshake()\n",
      "  File \"/srv/conda/envs/notebook/lib/python3.8/ssl.py\", line 1309, in do_handshake\n",
      "    self._sslobj.do_handshake()\n",
      "ssl.SSLCertVerificationError: [SSL: CERTIFICATE_VERIFY_FAILED] certificate verify failed: self signed certificate (_ssl.c:1124)\n",
      "\n",
      "During handling of the above exception, another exception occurred:\n",
      "\n",
      "Traceback (most recent call last):\n",
      "  File \"/srv/conda/envs/notebook/lib/python3.8/asyncio/events.py\", line 81, in _run\n",
      "    self._context.run(self._callback, *self._args)\n",
      "  File \"/srv/conda/envs/notebook/lib/python3.8/site-packages/tornado/platform/asyncio.py\", line 189, in _handle_events\n",
      "    handler_func(fileobj, events)\n",
      "  File \"/srv/conda/envs/notebook/lib/python3.8/site-packages/tornado/iostream.py\", line 696, in _handle_events\n",
      "    self._handle_read()\n",
      "  File \"/srv/conda/envs/notebook/lib/python3.8/site-packages/tornado/iostream.py\", line 1478, in _handle_read\n",
      "    self._do_ssl_handshake()\n",
      "  File \"/srv/conda/envs/notebook/lib/python3.8/site-packages/tornado/iostream.py\", line 1409, in _do_ssl_handshake\n",
      "    return self.close(exc_info=err)\n",
      "  File \"/srv/conda/envs/notebook/lib/python3.8/site-packages/tornado/iostream.py\", line 611, in close\n",
      "    self._signal_closed()\n",
      "  File \"/srv/conda/envs/notebook/lib/python3.8/site-packages/tornado/iostream.py\", line 641, in _signal_closed\n",
      "    self._ssl_connect_future.exception()\n",
      "asyncio.exceptions.CancelledError\n",
      "Exception in callback None()\n",
      "handle: <Handle cancelled>\n",
      "Traceback (most recent call last):\n",
      "  File \"/srv/conda/envs/notebook/lib/python3.8/site-packages/tornado/iostream.py\", line 1391, in _do_ssl_handshake\n",
      "    self.socket.do_handshake()\n",
      "  File \"/srv/conda/envs/notebook/lib/python3.8/ssl.py\", line 1309, in do_handshake\n",
      "    self._sslobj.do_handshake()\n",
      "ssl.SSLCertVerificationError: [SSL: CERTIFICATE_VERIFY_FAILED] certificate verify failed: self signed certificate (_ssl.c:1124)\n",
      "\n",
      "During handling of the above exception, another exception occurred:\n",
      "\n",
      "Traceback (most recent call last):\n",
      "  File \"/srv/conda/envs/notebook/lib/python3.8/asyncio/events.py\", line 81, in _run\n",
      "    self._context.run(self._callback, *self._args)\n",
      "  File \"/srv/conda/envs/notebook/lib/python3.8/site-packages/tornado/platform/asyncio.py\", line 189, in _handle_events\n",
      "    handler_func(fileobj, events)\n",
      "  File \"/srv/conda/envs/notebook/lib/python3.8/site-packages/tornado/iostream.py\", line 696, in _handle_events\n",
      "    self._handle_read()\n",
      "  File \"/srv/conda/envs/notebook/lib/python3.8/site-packages/tornado/iostream.py\", line 1478, in _handle_read\n",
      "    self._do_ssl_handshake()\n",
      "  File \"/srv/conda/envs/notebook/lib/python3.8/site-packages/tornado/iostream.py\", line 1409, in _do_ssl_handshake\n",
      "    return self.close(exc_info=err)\n",
      "  File \"/srv/conda/envs/notebook/lib/python3.8/site-packages/tornado/iostream.py\", line 611, in close\n",
      "    self._signal_closed()\n",
      "  File \"/srv/conda/envs/notebook/lib/python3.8/site-packages/tornado/iostream.py\", line 641, in _signal_closed\n",
      "    self._ssl_connect_future.exception()\n",
      "asyncio.exceptions.CancelledError\n",
      "Exception in callback None()\n",
      "handle: <Handle cancelled>\n",
      "Traceback (most recent call last):\n",
      "  File \"/srv/conda/envs/notebook/lib/python3.8/site-packages/tornado/iostream.py\", line 1391, in _do_ssl_handshake\n",
      "    self.socket.do_handshake()\n",
      "  File \"/srv/conda/envs/notebook/lib/python3.8/ssl.py\", line 1309, in do_handshake\n",
      "    self._sslobj.do_handshake()\n",
      "ssl.SSLCertVerificationError: [SSL: CERTIFICATE_VERIFY_FAILED] certificate verify failed: self signed certificate (_ssl.c:1124)\n",
      "\n",
      "During handling of the above exception, another exception occurred:\n",
      "\n",
      "Traceback (most recent call last):\n",
      "  File \"/srv/conda/envs/notebook/lib/python3.8/asyncio/events.py\", line 81, in _run\n",
      "    self._context.run(self._callback, *self._args)\n",
      "  File \"/srv/conda/envs/notebook/lib/python3.8/site-packages/tornado/platform/asyncio.py\", line 189, in _handle_events\n",
      "    handler_func(fileobj, events)\n",
      "  File \"/srv/conda/envs/notebook/lib/python3.8/site-packages/tornado/iostream.py\", line 696, in _handle_events\n",
      "    self._handle_read()\n",
      "  File \"/srv/conda/envs/notebook/lib/python3.8/site-packages/tornado/iostream.py\", line 1478, in _handle_read\n",
      "    self._do_ssl_handshake()\n",
      "  File \"/srv/conda/envs/notebook/lib/python3.8/site-packages/tornado/iostream.py\", line 1409, in _do_ssl_handshake\n",
      "    return self.close(exc_info=err)\n",
      "  File \"/srv/conda/envs/notebook/lib/python3.8/site-packages/tornado/iostream.py\", line 611, in close\n",
      "    self._signal_closed()\n",
      "  File \"/srv/conda/envs/notebook/lib/python3.8/site-packages/tornado/iostream.py\", line 641, in _signal_closed\n",
      "    self._ssl_connect_future.exception()\n",
      "asyncio.exceptions.CancelledError\n",
      "Exception in callback None()\n",
      "handle: <Handle cancelled>\n",
      "Traceback (most recent call last):\n",
      "  File \"/srv/conda/envs/notebook/lib/python3.8/site-packages/tornado/iostream.py\", line 1391, in _do_ssl_handshake\n",
      "    self.socket.do_handshake()\n",
      "  File \"/srv/conda/envs/notebook/lib/python3.8/ssl.py\", line 1309, in do_handshake\n",
      "    self._sslobj.do_handshake()\n",
      "ssl.SSLCertVerificationError: [SSL: CERTIFICATE_VERIFY_FAILED] certificate verify failed: self signed certificate (_ssl.c:1124)\n",
      "\n",
      "During handling of the above exception, another exception occurred:\n",
      "\n",
      "Traceback (most recent call last):\n",
      "  File \"/srv/conda/envs/notebook/lib/python3.8/asyncio/events.py\", line 81, in _run\n",
      "    self._context.run(self._callback, *self._args)\n",
      "  File \"/srv/conda/envs/notebook/lib/python3.8/site-packages/tornado/platform/asyncio.py\", line 189, in _handle_events\n",
      "    handler_func(fileobj, events)\n",
      "  File \"/srv/conda/envs/notebook/lib/python3.8/site-packages/tornado/iostream.py\", line 696, in _handle_events\n",
      "    self._handle_read()\n",
      "  File \"/srv/conda/envs/notebook/lib/python3.8/site-packages/tornado/iostream.py\", line 1478, in _handle_read\n",
      "    self._do_ssl_handshake()\n",
      "  File \"/srv/conda/envs/notebook/lib/python3.8/site-packages/tornado/iostream.py\", line 1409, in _do_ssl_handshake\n",
      "    return self.close(exc_info=err)\n",
      "  File \"/srv/conda/envs/notebook/lib/python3.8/site-packages/tornado/iostream.py\", line 611, in close\n",
      "    self._signal_closed()\n",
      "  File \"/srv/conda/envs/notebook/lib/python3.8/site-packages/tornado/iostream.py\", line 641, in _signal_closed\n",
      "    self._ssl_connect_future.exception()\n",
      "asyncio.exceptions.CancelledError\n",
      "Exception in callback None()\n",
      "handle: <Handle cancelled>\n",
      "Traceback (most recent call last):\n",
      "  File \"/srv/conda/envs/notebook/lib/python3.8/site-packages/tornado/iostream.py\", line 1391, in _do_ssl_handshake\n",
      "    self.socket.do_handshake()\n",
      "  File \"/srv/conda/envs/notebook/lib/python3.8/ssl.py\", line 1309, in do_handshake\n",
      "    self._sslobj.do_handshake()\n",
      "ssl.SSLCertVerificationError: [SSL: CERTIFICATE_VERIFY_FAILED] certificate verify failed: self signed certificate (_ssl.c:1124)\n",
      "\n",
      "During handling of the above exception, another exception occurred:\n",
      "\n",
      "Traceback (most recent call last):\n",
      "  File \"/srv/conda/envs/notebook/lib/python3.8/asyncio/events.py\", line 81, in _run\n",
      "    self._context.run(self._callback, *self._args)\n",
      "  File \"/srv/conda/envs/notebook/lib/python3.8/site-packages/tornado/platform/asyncio.py\", line 189, in _handle_events\n",
      "    handler_func(fileobj, events)\n",
      "  File \"/srv/conda/envs/notebook/lib/python3.8/site-packages/tornado/iostream.py\", line 696, in _handle_events\n",
      "    self._handle_read()\n",
      "  File \"/srv/conda/envs/notebook/lib/python3.8/site-packages/tornado/iostream.py\", line 1478, in _handle_read\n",
      "    self._do_ssl_handshake()\n",
      "  File \"/srv/conda/envs/notebook/lib/python3.8/site-packages/tornado/iostream.py\", line 1409, in _do_ssl_handshake\n",
      "    return self.close(exc_info=err)\n",
      "  File \"/srv/conda/envs/notebook/lib/python3.8/site-packages/tornado/iostream.py\", line 611, in close\n",
      "    self._signal_closed()\n",
      "  File \"/srv/conda/envs/notebook/lib/python3.8/site-packages/tornado/iostream.py\", line 641, in _signal_closed\n",
      "    self._ssl_connect_future.exception()\n",
      "asyncio.exceptions.CancelledError\n",
      "Exception in callback None()\n",
      "handle: <Handle cancelled>\n",
      "Traceback (most recent call last):\n",
      "  File \"/srv/conda/envs/notebook/lib/python3.8/site-packages/tornado/iostream.py\", line 1391, in _do_ssl_handshake\n",
      "    self.socket.do_handshake()\n",
      "  File \"/srv/conda/envs/notebook/lib/python3.8/ssl.py\", line 1309, in do_handshake\n",
      "    self._sslobj.do_handshake()\n",
      "ssl.SSLCertVerificationError: [SSL: CERTIFICATE_VERIFY_FAILED] certificate verify failed: self signed certificate (_ssl.c:1124)\n",
      "\n",
      "During handling of the above exception, another exception occurred:\n",
      "\n",
      "Traceback (most recent call last):\n",
      "  File \"/srv/conda/envs/notebook/lib/python3.8/asyncio/events.py\", line 81, in _run\n",
      "    self._context.run(self._callback, *self._args)\n",
      "  File \"/srv/conda/envs/notebook/lib/python3.8/site-packages/tornado/platform/asyncio.py\", line 189, in _handle_events\n",
      "    handler_func(fileobj, events)\n",
      "  File \"/srv/conda/envs/notebook/lib/python3.8/site-packages/tornado/iostream.py\", line 696, in _handle_events\n",
      "    self._handle_read()\n",
      "  File \"/srv/conda/envs/notebook/lib/python3.8/site-packages/tornado/iostream.py\", line 1478, in _handle_read\n",
      "    self._do_ssl_handshake()\n",
      "  File \"/srv/conda/envs/notebook/lib/python3.8/site-packages/tornado/iostream.py\", line 1409, in _do_ssl_handshake\n",
      "    return self.close(exc_info=err)\n",
      "  File \"/srv/conda/envs/notebook/lib/python3.8/site-packages/tornado/iostream.py\", line 611, in close\n",
      "    self._signal_closed()\n",
      "  File \"/srv/conda/envs/notebook/lib/python3.8/site-packages/tornado/iostream.py\", line 641, in _signal_closed\n",
      "    self._ssl_connect_future.exception()\n",
      "asyncio.exceptions.CancelledError\n",
      "Exception in callback None()\n",
      "handle: <Handle cancelled>\n",
      "Traceback (most recent call last):\n",
      "  File \"/srv/conda/envs/notebook/lib/python3.8/site-packages/tornado/iostream.py\", line 1391, in _do_ssl_handshake\n",
      "    self.socket.do_handshake()\n",
      "  File \"/srv/conda/envs/notebook/lib/python3.8/ssl.py\", line 1309, in do_handshake\n",
      "    self._sslobj.do_handshake()\n",
      "ssl.SSLCertVerificationError: [SSL: CERTIFICATE_VERIFY_FAILED] certificate verify failed: self signed certificate (_ssl.c:1124)\n",
      "\n",
      "During handling of the above exception, another exception occurred:\n",
      "\n",
      "Traceback (most recent call last):\n",
      "  File \"/srv/conda/envs/notebook/lib/python3.8/asyncio/events.py\", line 81, in _run\n",
      "    self._context.run(self._callback, *self._args)\n",
      "  File \"/srv/conda/envs/notebook/lib/python3.8/site-packages/tornado/platform/asyncio.py\", line 189, in _handle_events\n",
      "    handler_func(fileobj, events)\n",
      "  File \"/srv/conda/envs/notebook/lib/python3.8/site-packages/tornado/iostream.py\", line 696, in _handle_events\n",
      "    self._handle_read()\n",
      "  File \"/srv/conda/envs/notebook/lib/python3.8/site-packages/tornado/iostream.py\", line 1478, in _handle_read\n",
      "    self._do_ssl_handshake()\n",
      "  File \"/srv/conda/envs/notebook/lib/python3.8/site-packages/tornado/iostream.py\", line 1409, in _do_ssl_handshake\n",
      "    return self.close(exc_info=err)\n",
      "  File \"/srv/conda/envs/notebook/lib/python3.8/site-packages/tornado/iostream.py\", line 611, in close\n",
      "    self._signal_closed()\n",
      "  File \"/srv/conda/envs/notebook/lib/python3.8/site-packages/tornado/iostream.py\", line 641, in _signal_closed\n",
      "    self._ssl_connect_future.exception()\n",
      "asyncio.exceptions.CancelledError\n"
     ]
    }
   ],
   "source": [
    "uo_rg_eq=uo_regrid.sel(lat=slice(-5,5)).mean('lat')\n",
    "uo_rg_eq.load()\n",
    "uo_rg_eq.to_netcdf('uo_eq_'+'HadGEM3-GC31-LL'+'_ens1.nc')\n",
    "\n",
    "vo_rg_eq=abs(vo_regrid.sel(lat=slice(-5,5))*vo_regrid).lat.sel(lat=slice(-5,5))\n",
    "vo_rg_eq=vo_rg_eq.mean('lat')\n",
    "vo_rg_eq.load()\n",
    "vo_rg_eq.to_netcdf('vo_eq_'+'HadGEM3-GC31-LL'+'_ens1.nc')\n",
    "\n",
    "wo_rg_eq=wo_regrid.sel(lat=slice(-5,5)).mean('lat')\n",
    "wo_rg_eq.load()\n",
    "wo_rg_eq.to_netcdf('wo_eq_'+'HadGEM3-GC31-LL'+'_ens1.nc')"
   ]
  },
  {
   "cell_type": "code",
   "execution_count": 13,
   "id": "hydraulic-mortgage",
   "metadata": {},
   "outputs": [
    {
     "data": {
      "text/html": [
       "<div>\n",
       "<style scoped>\n",
       "    .dataframe tbody tr th:only-of-type {\n",
       "        vertical-align: middle;\n",
       "    }\n",
       "\n",
       "    .dataframe tbody tr th {\n",
       "        vertical-align: top;\n",
       "    }\n",
       "\n",
       "    .dataframe thead th {\n",
       "        text-align: right;\n",
       "    }\n",
       "</style>\n",
       "<table border=\"1\" class=\"dataframe\">\n",
       "  <thead>\n",
       "    <tr style=\"text-align: right;\">\n",
       "      <th></th>\n",
       "      <th>activity_id</th>\n",
       "      <th>institution_id</th>\n",
       "      <th>source_id</th>\n",
       "      <th>experiment_id</th>\n",
       "      <th>member_id</th>\n",
       "      <th>table_id</th>\n",
       "      <th>variable_id</th>\n",
       "      <th>grid_label</th>\n",
       "      <th>zstore</th>\n",
       "      <th>dcpp_init_year</th>\n",
       "      <th>version</th>\n",
       "    </tr>\n",
       "  </thead>\n",
       "  <tbody>\n",
       "    <tr>\n",
       "      <th>207071</th>\n",
       "      <td>CMIP</td>\n",
       "      <td>MOHC</td>\n",
       "      <td>HadGEM3-GC31-LL</td>\n",
       "      <td>abrupt-4xCO2</td>\n",
       "      <td>r1i1p1f3</td>\n",
       "      <td>Omon</td>\n",
       "      <td>thetao</td>\n",
       "      <td>gn</td>\n",
       "      <td>gs://cmip6/CMIP6/CMIP/MOHC/HadGEM3-GC31-LL/abr...</td>\n",
       "      <td>NaN</td>\n",
       "      <td>20190620</td>\n",
       "    </tr>\n",
       "  </tbody>\n",
       "</table>\n",
       "</div>"
      ],
      "text/plain": [
       "       activity_id institution_id        source_id experiment_id member_id  \\\n",
       "207071        CMIP           MOHC  HadGEM3-GC31-LL  abrupt-4xCO2  r1i1p1f3   \n",
       "\n",
       "       table_id variable_id grid_label  \\\n",
       "207071     Omon      thetao         gn   \n",
       "\n",
       "                                                   zstore  dcpp_init_year  \\\n",
       "207071  gs://cmip6/CMIP6/CMIP/MOHC/HadGEM3-GC31-LL/abr...             NaN   \n",
       "\n",
       "         version  \n",
       "207071  20190620  "
      ]
     },
     "execution_count": 13,
     "metadata": {},
     "output_type": "execute_result"
    }
   ],
   "source": [
    "theta"
   ]
  },
  {
   "cell_type": "code",
   "execution_count": 13,
   "id": "boxed-astrology",
   "metadata": {},
   "outputs": [],
   "source": [
    "tauu_eq=tauu_eq.mean('lat')\n",
    "tauu_eq.load()\n",
    "tauu_eq.to_netcdf('tauu_eq_'+'HadGEM3-GC31-LL'+'_4x.nc')\n",
    "\n",
    "Q_eq=Q_eq.mean('lat')\n",
    "Q_eq.load()\n",
    "Q_eq.to_netcdf('Q_eq_'+'HadGEM3-GC31-LL'+'_4x.nc')"
   ]
  },
  {
   "cell_type": "code",
   "execution_count": 59,
   "id": "conscious-houston",
   "metadata": {},
   "outputs": [
    {
     "data": {
      "text/html": [
       "<div>\n",
       "<style scoped>\n",
       "    .dataframe tbody tr th:only-of-type {\n",
       "        vertical-align: middle;\n",
       "    }\n",
       "\n",
       "    .dataframe tbody tr th {\n",
       "        vertical-align: top;\n",
       "    }\n",
       "\n",
       "    .dataframe thead th {\n",
       "        text-align: right;\n",
       "    }\n",
       "</style>\n",
       "<table border=\"1\" class=\"dataframe\">\n",
       "  <thead>\n",
       "    <tr style=\"text-align: right;\">\n",
       "      <th></th>\n",
       "      <th>activity_id</th>\n",
       "      <th>institution_id</th>\n",
       "      <th>source_id</th>\n",
       "      <th>experiment_id</th>\n",
       "      <th>member_id</th>\n",
       "      <th>table_id</th>\n",
       "      <th>variable_id</th>\n",
       "      <th>grid_label</th>\n",
       "      <th>zstore</th>\n",
       "      <th>dcpp_init_year</th>\n",
       "      <th>version</th>\n",
       "    </tr>\n",
       "  </thead>\n",
       "  <tbody>\n",
       "    <tr>\n",
       "      <th>396417</th>\n",
       "      <td>ScenarioMIP</td>\n",
       "      <td>MOHC</td>\n",
       "      <td>HadGEM3-GC31-LL</td>\n",
       "      <td>ssp585</td>\n",
       "      <td>r1i1p1f3</td>\n",
       "      <td>Omon</td>\n",
       "      <td>thetao</td>\n",
       "      <td>gn</td>\n",
       "      <td>gs://cmip6/CMIP6/ScenarioMIP/MOHC/HadGEM3-GC31...</td>\n",
       "      <td>NaN</td>\n",
       "      <td>20200114</td>\n",
       "    </tr>\n",
       "  </tbody>\n",
       "</table>\n",
       "</div>"
      ],
      "text/plain": [
       "        activity_id institution_id        source_id experiment_id member_id  \\\n",
       "396417  ScenarioMIP           MOHC  HadGEM3-GC31-LL        ssp585  r1i1p1f3   \n",
       "\n",
       "       table_id variable_id grid_label  \\\n",
       "396417     Omon      thetao         gn   \n",
       "\n",
       "                                                   zstore  dcpp_init_year  \\\n",
       "396417  gs://cmip6/CMIP6/ScenarioMIP/MOHC/HadGEM3-GC31...             NaN   \n",
       "\n",
       "         version  \n",
       "396417  20200114  "
      ]
     },
     "execution_count": 59,
     "metadata": {},
     "output_type": "execute_result"
    }
   ],
   "source": [
    "theta"
   ]
  },
  {
   "cell_type": "code",
   "execution_count": null,
   "id": "strategic-overview",
   "metadata": {},
   "outputs": [],
   "source": []
  }
 ],
 "metadata": {
  "kernelspec": {
   "display_name": "Python 3",
   "language": "python",
   "name": "python3"
  },
  "language_info": {
   "codemirror_mode": {
    "name": "ipython",
    "version": 3
   },
   "file_extension": ".py",
   "mimetype": "text/x-python",
   "name": "python",
   "nbconvert_exporter": "python",
   "pygments_lexer": "ipython3",
   "version": "3.8.6"
  }
 },
 "nbformat": 4,
 "nbformat_minor": 5
}
